<?xml version="1.0"?>
<robot name="diffbot" xmlns:xacro="http://www.ros.org/wiki/xacro">

  <!-- LINKS -->
  <link name="base_link"/>
  <link name="left_wheel"/>
  <link name="right_wheel"/>

  <!-- JOINTS -->
  <joint name="left_wheel_joint" type="continuous">
    <parent link="base_link"/>
    <child link="left_wheel"/>
    <axis xyz="0 1 0"/>
  </joint>

  <joint name="right_wheel_joint" type="continuous">
    <parent link="base_link"/>
    <child link="right_wheel"/>
    <axis xyz="0 1 0"/>
  </joint>

  <!-- ROS2 CONTROL -->
  <ros2_control name="TeensySystem" type="system">
    <hardware>
      <plugin>diffbot_hardware/TeensyDiffDrive</plugin>

      <param name="serial_port">/dev/ttyACM0</param>
      <param name="baudrate">115200</param>
    </hardware>

    <joint name="left_wheel_joint">
      <command_interface name="velocity"/>
      <state_interface name="position"/>
      <state_interface name="velocity"/>
    </joint>

    <joint name="right_wheel_joint">
      <command_interface name="velocity"/>
      <state_interface name="position"/>
      <state_interface name="velocity"/>
    </joint>
  </ros2_control>
  
   <!-- <xacro:diffbot_ros2_control/> -->

</robot>
